let a = 5;
let b = 6;
console.log(a);
console.log(b);
console.log(a+b);
console.log(a+b);
try{
    console.log(a+c); // this line might throw an error so we put it inside the try and catch block
}
catch(err){
    console.log(err);
}
// this will make sure that the code doesn't stop even after the error
console.log(a+b);
console.log(a+b);
console.log(a+b);
console.log(a+b);